Workbook

Sheet Cert
B3: Calibration Certificate | F3: Certification Control: no. | H3: 23196 | I3: P
B4: Customer: | C4: Siemens Energy - Sam Houston | F4: Procedure | Accuracy: | H4: WS-WP-7.2
B5: Contact: | C5: =VLOOKUP(C4,'DATA - CUSTOMER'!A2:J120,3,FALSE) -> Steven Lumpkin | F5: Calibration Date: | H5: 46213
B6: Address: | C6: =VLOOKUP(C4,'DATA - CUSTOMER'!A2:J1200,4,FALSE) -> 1200 West Sam Houston Parkway North | F6: Due Date: | H6: 46578
C7: =VLOOKUP(C4,'DATA - CUSTOMER'!A2:J1200,6,FALSE) -> Houston,TX 77043 | F7: Frequency | Interval: | H7: 12 Months
B8: Phone: | C8: =VLOOKUP(C4,'DATA - CUSTOMER'!A2:J120,10,FALSE) -> 713-301-8678 | F8: Temp (F) & Humidity: | H8: 71.4° F | 38%
B9: PO No.: | F9: New/ Recal: | H9: RECAL
B11: PSI | C11: 30000 | F11: S/N: | G11: 2583
B12: Manuf. | C12: MCDANIEL | F12: Model: | G12: ANALOG GAUGE
B13: As Found (Increasing) | F13: As Left (Increasing)
B14: Pressure Gauge (PSI) | C14: Standard Output (PSI) | D14: Precent Deviation | F14: Pressure Gauge (PSI) | G14: Standard Output (PSI) | H14: Precent Deviation
B15: 0 | C15: 0 | D15: 0 | F15: =B15 -> 0 | G15: =C15 -> 0 | H15: =D15 -> 0
B16: =C11/5*1 -> 6000 | C16: 5973 | D16: =(C16-B16)/B16 -> -0.0045 | F16: =B16 -> 6000 | G16: =C16 -> 5973 | H16: =(G16-F16)/F16 -> -0.0045
B17: =C11/5*2 -> 12000 | C17: 11994 | D17: =(C17-B17)/B17 -> -0.0005 | F17: =B17 -> 12000 | G17: =C17 -> 11994 | H17: =D17 -> -0.0005
B18: =C11/5*3 -> 18000 | C18: 17983 | D18: =(C18-B18)/B18 -> -0.00094444444 | F18: =B18 -> 18000 | G18: =C18 -> 17983 | H18: =D18 -> -0.00094444444
B19: =B20/5*4 -> 24000 | C19: 23988 | D19: =(C19-B19)/B19 -> -0.0005 | F19: =B19 -> 24000 | G19: =C19 -> 23988 | H19: =D19 -> -0.0005
B20: =C11 -> 30000 | C20: 29971 | D20: =(C20-B20)/B20 -> -0.00096666667 | F20: =B20 -> 30000 | G20: =C20 -> 29971 | H20: =D20 -> -0.00096666667
B21: As Found (decreasing) | F21: As Left (decreasing)
B22: Pressure Gauge (PSI) | C22: Standard Output (PSI) | D22: Precent Deviation | F22: Pressure Gauge (PSI) | G22: Standard Output (PSI) | H22: Precent Deviation
B23: =B20 -> 30000 | C23: =C20 -> 29971 | D23: =D20 -> -0.00096666667 | F23: =B20 -> 30000 | G23: =C20 -> 29971 | H23: =H20 -> -0.00096666667
B24: =B19 -> 24000 | C24: =C19 -> 23988 | D24: =D19 -> -0.0005 | F24: =B24 -> 24000 | G24: =C24 -> 23988 | H24: =H19 -> -0.0005
B25: =B18 -> 18000 | C25: =C18 -> 17983 | D25: =D18 -> -0.00094444444 | F25: =B25 -> 18000 | G25: =C25 -> 17983 | H25: =H18 -> -0.00094444444
B26: =B17 -> 12000 | C26: =C17 -> 11994 | D26: =H17 -> -0.0005 | F26: =B26 -> 12000 | G26: =C26 -> 11994 | H26: =D26 -> -0.0005
B27: =B16 -> 6000 | C27: =C16 -> 5973 | D27: =(C27-B27)/B27 -> -0.0045 | F27: =B27 -> 6000 | G27: =C16 -> 5973 | H27: =(G27-F27)/F27 -> -0.0045
B28: 0 | C28: 0 | D28: 0 | F28: =B28 -> 0 | G28: =C28 -> 0 | H28: 0
A31: Calibration Standard
A32: Brand: | B32: Item: | C32: Model | D32: S/N | E32: Due Date | G32: Traceability | I32: Accuracy
A33: =VLOOKUP(C33,'Data - Standards'!A2:I18,2,FALSE) -> ADDITEL | B33: =VLOOKUP(C33,'Data - Standards'!A2:I18,3,FALSE) -> GAUGE | C33: ADT-681-60K | D33: =VLOOKUP(C33,'Data - Standards'!A2:I18,4,FALSE) -> 218231A0029 | E33: =VLOOKUP(C33,'Data - Standards'!A2:I18,5,FALSE) -> 46554 | G33: =VLOOKUP(C33,'Data - Standards'!A2:I18,6,FALSE) -> N24061747 | I33: =VLOOKUP(C33,'Data - Standards'!A2:I18,7,FALSE) -> ±0.25%
A34: The calibrations within the certificate/report are traceable through NIST or another National Metrology Institute to the International System of Units (SI). The results only relate to the items tested, calibrated, or sampled. The reported expanded uncertainty of measurement is stated as the standard uncertainty of measurement multiplied by the coverage factor k=2, which for a normal distribution corresponds to a coverage probability of approximately 95%. Simple acceptance decision rule were uncertainty is not factored into the tolerance for conformity.
A40: Calibrated by: | C40: David Bain | F40: Approved by: | H40: DAVID SHAW
C41: E-Signed: | D41: =H5 -> 46213 | H41: E-Signed: | I41: =D41 -> 46213
A42: Comments:

Sheet DATA - CUSTOMER
A1: <Choose Company> | B1: Company | C1: Contact | D1: Addr1 | E1: Addr2 | F1: City, State,Zip | H1: Zip | I1: Country | J1: Phone | K1: Fax | L1: blah | M1: blah | N1: blah | O1: Old
A2: 3C METAL | B2: 3C Metal | C2: Edourd Villaret | D2: 11983-A FM 529 | F2: Houston, TX 77056 | G2: TX | H2: 77041 | I2: USA | J2: (713) 808-9651 | O2: 2
A3: 3D At Depth | B3: 3D At Depth | C3: Alfredo Escobedo | D3: 2901 W Sam Houston Pkwy N Suite A-150 | F3: Houston, TX 77043 | G3: TX | H3: 77043 | I3: USA | J3: (713) 966-6779
A4: A&M Equipment LLC. | B4: A&M Equipment LLC. | C4: Keith Matetzschk | D4: 28246 FM 2920 Rd. | F4: Waller, TX 77484 | G4: Tx | H4: 77484 | I4: USA | J4: (979) 525-4431
A5: ACE WINCHES | B5: ACE WINCHES | C5: STEVEN SMITH | D5: TOWIE BARCLAY WORKS | F5: TURRIFF, ABERDEENSHIRE | H5: AB538EN | I5: UK | J5: 44 7768 067324
A6: ACFM | B6: Howden | C6: Roosevelt Bruins | D6: 16250 Tomball Pkwy | F6: Houston, TX 77086 | G6: TX | H6: 77086 | I6: USA | J6: (936) 539-5252 | K6: (936) 539-5251 | O6: 3
A7: AIR PRODUCT | B7: AIR PRODUCT | C7: JOSE G CONTRERAS | D7: 10202 STRANF RD | F7: LAPORTE | G7: TX | I7: USA | J7: 832-547-1897
A8: Baker Hughes - Brittmore | B8: Baker Hughes | C8: James Brooks | D8: 6500 Brittmore RD. | F8: Houston, TX 77041 | G8: TX | H8: 77041 | I8: USA | J8: (281) 529-2400
A9: Bestway Oilfield Inc. | B9: Bestway Oilfield Inc. | C9: Hector Lopez | D9: 3471 W. State Hwy 44 | F9: Alice, TX 78333 | G9: Tx | H9: 78333 | I9: USA | J9: 281-452-2525
A10: Bolttech Mannings | B10: Bolttech Mannings | C10: Quality Department | D10: 290 Beltway Green Blvd | F10: Deer Park, TX 77536 | G10: Tx | H10: 77536 | I10: USA
A11: C-Automation | B11: C-Automation | C11: Randall Stockton | D11: 10535 Fisher Rd | F11: Houston, TX 77041 | G11: TX | H11: 77041 | I11: USA | J11: 832-467-4644
A12: DRIL QUIP | B12: Dril Quip | C12: EFRAIN VILLASENOR | D12: 6401 N Eldridge Pkwy | F12: Houston, TX 77041 | G12: Tx | H12: 77041 | I12: USA | J12: 281-425-5086
A13: D-Tech Calibration | B13: D-Tech Calibration | C13: Calibration Department | D13: 16151 Cairnway Dr. Suite 100 | F13: Houston, TX 77084 | G13: TX | H13: 77084 | I13: USA | J13: 832-674-4961
A14: Enermech | B14: Enermech | C14: Xavier Ochoa | D14: 12101 CUTTEN RD | F14: HOUSTON, TX 77066 | G14: TX | H14: 77066 | I14: USA | J14: 979-571-2820 | O14: 5
A15: Engineered Custom Solutions, | B15: Engineered Custom Solutions, LLC. | C15: Tam Nguyen | D15: 13720 FM 529 Rd | F15: Houston, TX 77041 | G15: TX | H15: 77041 | I15: USA | J15: (832) 598-2083
A16: Fastenal | B16: Fastenal | C16: Jacob Tackett | D16: 201 Bryan St. | F16: Dayton, TX 77535 | G16: Texas | H16: 77535 | I16: USA | J16: (936) 258-2671 | O16: 6
A17: Fastenal (#2) | B17: Fastenal | C17: Chris Conrad | D17: 501B East Heil Ave. | F17: El Centro, CA 92243 | G17: CA | H17: 92243 | I17: USA | J17: (760)-352-2313 | O17: 7
A18: Fastenal Clute | B18: Fastenal Clute | C18: Rodney Kifer | D18: 734 S Main St, | F18: Clute, TX 77531 | G18: tx | H18: 77531 | I18: USA | J18: 979-265-2252
A19: Flatiron | B19: Flatiron | C19: Micah Murphy | D19: 817 Brewster ST | F19: Corpus C, TX 78401 | G19: Tx | H19: 78401 | I19: USA | J19: 281-946-4000
A20: Genesis Solar | B20: Genesis Solar | C20: Michael Medsker | D20: 11995 Wiley's Well Rd | F20: Blythe, CA 92225 | G20: CA | H20: 92225 | I20: USA | J20: 760-921-1409
A21: GRIZZLY | B21: Grizzly | C21: Kirk French | D21: 41303 park 290 drive | F21: Waller, TX 77484 | G21: Texas | H21: 77484 | I21: USA | J21: 710-926-5544 | O21: 8
A22: Herc Rentals Inc. | B22: Herc Rentals Inc. | C22: Lin Mendez | D22: 1002 Clay Ct | F22: Deer Park, TX 77536 | G22: TX | H22: 77536 | I22: USA | J22: 281-478-7921
A23: HOUSTON PRECISION | B23: HOUSTON PRECISION | C23: ANDREA DeLEON | D23: 6633 POLK STREET | F23: Houston, TX 77011 | G23: TX | H23: 77011 | I23: USA | O23: 27
A24: HP Piping | B24: HP Piping | C24: Thomas Mitchmore | D24: 4311 holmes Rd | F24: Houston, TX 77051 | G24: Texas | H24: 77051 | I24: USA | J24: 832-582-8898 | O24: 9
A25: Hughes-Anderson Heat Exchanger | B25: Hughes-Anderson Heat Exchanger | C25: Kelly Bock | D25: PO Box 582710 | F25: Tulsa, OK 74158 | G25: OK | H25: 74158 | I25: USA | J25: 918 836-1681
A26: Hurricane Tool | B26: Hurricane Tool | C26: Brittany Mason | D26: 2330 Pasadena Blvd., Bldg A | F26: Pasadena, TX 77502 | G26: TX | H26: 77502 | I26: USA | J26: 281-476-5530
A27: HYTORC | B27: HYTORC
A28: Hytorc North | B28: Hytorc North | C28: Tina Moss | D28: 311 Taft St | F28: Palmyra, WI 53156 | G28: WI | H28: 53156 | I28: USA | J28: 262-510-9587
A29: INTEGRA Technologies | B29: INTEGRA Technologies | C29: Jared Priddy | D29: 5812 Genoa Red Bluff Rd | F29: Pasadena, TX 77507 | G29: Tx | H29: 77507 | I29: USA | J29: 713-920-2400
A30: K2 | B30: Applus K2 | C30: James Rushforth | D30: 11801 West Sam Houston Parkway | F30: Houston, TX 77031 | G30: TX | H30: 77031 | I30: USA | J30: (832) 454-1555 | O30: 10
A31: Kirksey Machine | B31: Kirksey Machine | C31: Cody Moore | D31: 8721 Clay Rd. | F31: Houston, TX 77292 | G31: Tx | H31: 77292 | I31: USA | J31: 713-682-6704
A32: MAN Energy Solutions USA Inc. | B32: MAN Energy Solutions USA Inc. | C32: Curtis Chandler | D32: 1758 Twinwood Pkwy | F32: Brookshire,Tx 77423 | G32: Tx | H32: 77423 | I32: USA | J32: (713) 780-4200
A33: MSI | B33: Measurement Systems and Services, Inc. | C33: David Klasen | D33: 5010 Steffani Lane | F33: Houston, TX 77041 | G33: TX | H33: 77041 | I33: USA | J33: - | O33: 11
A34: Mustang CAT | B34: Mustang CAT | C34: Alfred James III | D34: 12800 Northwest Freeway | F34: Houston, TX 77040 | G34: TX | H34: 77040 | I34: USA | J34: 713-452-7205 | O34: 27
A35: Nabors | B35: Nabors Drilling Solutions | C35: Joey Peregne | D35: 515 W. Greens Road Suite 110 | F35: Houston, TX 77067 | G35: TX | H35: 77067 | I35: USA | J35: (281) 874-0035 | O35: 12
A36: Nabors Breen | B36: Nabors Breen | C36: Jeremy X | D36: 8400 Breen Rd | F36: Houston, Tx 77064 | G36: Tx | H36: 77064 | I36: USA | J36: 832-405-8697
A37: NABORS CROSBY | B37: NABORS CROSBY | C37: Orlando Sanchez | D37: 2100 Crosby Dayton Rd | F37: Crosby, TX 77532 | G37: TX | H37: 77532 | I37: USA | J37: 281.618.4111
A38: Nextera Energy | B38: Nextera Energy | C38: Michael Medsker | D38: 601 Travis St | F38: Houston, 77002 | G38: TX | H38: 77002 | I38: USA | J38: 760-921-1409 | O38: 13
A39: NOV | B39: Metrology Lab WLY/NOV | C39: Roosevelt Perez | D39: 12950 West Little York Rd | F39: Houston, TX 77041 | G39: Texas | H39: 77041 | I39: USA | J39: 713-501-7784 | O39: 14
A40: NOV 529 | B40: NOV/ Metrology Lab | C40: Eric Aguirre | D40: 11919 FM 529 RD | F40: Houston, TX 77041 | G40: TX | H40: 77041 | I40: USA | J40: 832-424-7774 | O40: 15
...

Sheet Data - Standards
A1: Model | B1: Brand: | C1: Item: | D1: S/N | E1: Due Date | F1: Traceability | G1: Accuracy | H1: Current Date | I1: Days Left | J1: Ownership
A2: XP2i 15k | B2: CRYSTAL | C2: GAUGE | D2: 562009 | E2: 47035 | F2: 1194717 | G2: ±0.25% | H2: =TODAY() -> 46216 | I2: =E2-H2 -> 819 | J2: WINSHAW | N2: Recall Interval: | O2: New / Recal: | P2: Testing Procedure:
A3: XP2i 10k | B3: CRYSTAL | C3: GAUGE | D3: 561154 | E3: 46317 | F3: A1389576 | G3: ±0.25% | H3: =TODAY() -> 46216 | I3: =E3-H3 -> 101 | J3: WINSHAW | N3: 3 Months | O3: NEW | P3: WS-WP-7.2
A4: ADT-681-60K | B4: ADDITEL | C4: GAUGE | D4: 218231A0029 | E4: 46554 | F4: N24061747 | G4: ±0.25% | H4: =TODAY() -> 46216 | I4: =E4-H4 -> 338 | J4: WINSHAW | N4: 6 Months | O4: RECAL | P4: CP-43 - Torque - Rev. 6
A5: CPB5000 | B5: bedenburg | C5: GAUGE | D5: 34342 | E5: 46138 | F5: 30644R | H5: =TODAY() -> 46216 | I5: =E5-H5 -> -78 | N5: 9 Months | P5: CP-56 - Torque - Rev.6
A6: 2,500 - 60,000 LBF | B6: COTI INC | C6: GAUGE | D6: 5-1017 | E6: 46227 | F6: 1141729 | G6: ±1% | H6: =TODAY() -> 46216 | I6: =E6-H6 -> 11 | J6: Holloway Houston | N6: 12 Months | P6: CP-76 - Pressure - Rev.7
A7: SW30-100K-B363 | B7: TOVEY | C7: Pressure Transducer | D7: 132312A | E7: 46809 | F7: 684.07/O-0000058461 | G7: ±1% | H7: =TODAY() -> 46216 | I7: =E7-H7 -> 593 | J7: WINSHAW | N7: 24 Months | P7: COMPRESSION
A8: 7230 | B8: TOVEY | C8: Digital Indicator | D8: 17818127 | E8: 46809 | F8: 684.06/O-0000035085-21 | G8: ±1% | H8: =TODAY() -> 46216 | I8: =E8-H8 -> 593 | J8: WINSHAW | P8: COPS-QM-PRO-003 REV:F
I9: =E9-H9 -> 0 | P9: CP-50 - Weight - Rev. 4
A10: 30k Chart Record | B10: Barton | C10: 30k Chart Record | D10: 242E-060413R | E10: 45946 | F10: 154022 | G10: ±1% | H10: =TODAY() -> 46216 | I10: =E10-H10 -> -270 | P10: CP-100 - Fluid Control - Rev.2
A11: THERMOMETER | B11: TRACE | C11: THERMOMETER | D11: 200141856 | E11: 46350 | F11: 35499 | G11: ±0.1% | H11: =TODAY() -> 46216 | I11: =E11-H11 -> 134 | J11: OGME
